Workbook

Sheet 利润试算表
A1: f | B1: 142 | I1: 填写格 | K1: 不要修改 | M1: 信封大 | N1: 34x24x2
I2: 计算格 | K2: 实际测量体积 | M2: 信封中 | N2: 28.5x20x2
A3: EC site URL | B3: eBayURL | C3: ItemID（SKU) | D3: 刊登 | E3: 优化 | F3: 视频 | G3: UPC | H3: 广告费 | I3: 价格折扣 | J3: 采购价格 （日） | K3: JP重量 (g) | L3: 长 （cm） | M3: 高 （cm) | N3: 高 （cm) | O3: OC重量 （g) | P3: 销售价格 USD | Q3: 物流费用 US外 | R3: 物流定价 US | S3: 增加成本 US | T3: 总价 US | U3: SP运费 | V3: 关税及 手续费 | W3: eBay 佣金 | X3: 海外 手数料 | Y3: 利润 （US外） | Z3: 利润率 （US外） | AA3: ROI （US外） | AB3: 利润 （US） | AC3: 利润率 （US） | AD3: ROI （US） | AE3: eBay费用 （US外） | AF3: eBay费用 （US） | AG3: 备注
A4: 例子 | B4: 例子 | C4: 01-2507-0003 | G4: 这一行不要改 | H4: 0.05 | I4: 0 | J4: 2000 | K4: 210 | L4: 34 | M4: 24 | N4: 2 | O4: =max(L4*M4*N4/8000*1000,K4) -> 210 | P4: 36.43 | Q4: {=XLOOKUP(K4/1000, '运费（邮政）'!$A$2:$A$21, '运费（邮政）'!$B$2:$B$21, "超出范围", 1)} -> 1240 | R4: 12 | S4: =(V4+U4-Q4)/$B$1 -> 7.7054185 | T4: =P4+R4 -> 48.43 | U4: {=XLOOKUP(O4/1000, '运费（橙联）'!$A$2:$A$57, '运费（橙联）'!$B$2:$B$57, "超出范围", 1)} -> 1581 | V4: =(P4*'参数表'!$C$2*(1+'参数表'!$C$3))*$B$1+'参数表'!$C$4 -> 753.16943 | W4: 0.127 | X4: 0.0135 | Y4: =(P4*(1-I4)-AE4)*$B$1-J4-Q4 -> 678.1638 | Z4: =Y4/P4/$B$1 -> 0.13109529 | AA4: =Y4/J4 -> 0.3390819 | AB4: =(P4*(1-I4)+R4-AF4)*$B$1-J4-U4-V4 -> 930.92118 | AC4: =AB4/T4/$B$1 -> 0.13536616 | AD4: =AB4/J4 -> 0.46546059 | AE4: =P4*(1-I4)*(1+'参数表'!$C$6)*(W4+X4+H4)*1.1+0.4*1.1 -> 8.8372971 | AF4: =(P4*(1-I4)*1.1+R4)*(W4+X4+H4)*1.1+0.4*1.1 -> 11.351897
A5: https://www.amazon.co.jp/PILOT-%E3%83%9C%E3%83%BC%E3%83%AB%E3%83%9A%E3%83%B3-%E3%82%B8%E3%83%A5%E3%83%BC%E3%82%B9%E3%83%97%E3%83%A9%E3%82%B93%E8%89%B2%E3%82%BB%E3%83%83%E3%83%88-0-4mm-LJL143CA/dp/B0FW4M3LH7/ref=sr_1_9?crid=3NWFUPINP4YPW&dib=eyJ2IjoiMSJ9.VoEIf6XsPD72Nnsq7obLDQNFAPoKxm4HuckZ4JaCj4hrQ3AllLYOmNO1gDAC2gMX5ZSuyQGaPOAEsyfzCt7MTBgedsxRSQVj7F3bURQv7g8c8tQHHxUEbSjdHLeeQigHKetmvJk2KpWQOIjCG6s_t95rlO1w2uJI646uZHkCZyA0ojXqT4QFQXnnkpBXb1Zg73If2Hnmp9r_WE1N6s5gW-Xg2Z3XR1AsDwDro3TVsGGcwJo2CPfkyGQFpSSC0EZajSj7FF7jPxheONdsqC3JxExu9U5fga9QDSNFv2NtbVY.nzwlsZPC1vN2AGRLcmx8r_1CD4JyD5CVIorNudhCbdY&dib_tag=se&keywords=pilot%2Bjuice%2B&qid=1768525949&sprefix=pilot%2Bjuice%2B%2Caps%2C293&sr=8-9&th=1 | C5: 01-2601-0074 | D5: 没货 | F5: 可直接上3个的套装 | H5: 0.05 | I5: 0 | L5: 34 | M5: 24 | N5: 2 | O5: =max(L5*M5*N5/8000*1000,K5) -> 204 | Q5: {=XLOOKUP(K5/1000, '运费（邮政）'!$A$2:$A$21, '运费（邮政）'!$B$2:$B$21, "超出范围", 1)} -> 880 | S5: =(V5+U5-Q5)/$B$1 -> 6.5211268 | T5: =P5+R5 -> 0 | U5: {=XLOOKUP(O5/1000, '运费（橙联）'!$A$2:$A$57, '运费（橙联）'!$B$2:$B$57, "超出范围", 1)} -> 1581 | V5: =(P5*'参数表'!$C$2*(1+'参数表'!$C$3))*$B$1+'参数表'!$C$4 -> 225 | W5: 0.127 | X5: 0.0135 | Y5: =(P5*(1-I5)-AE5)*$B$1-J5-Q5 -> -942.48 | Z5: =Y5/P5/$B$1 -> #DIV/0! | AA5: =Y5/J5 -> #DIV/0! | AB5: =(P5*(1-I5)+R5-AF5)*$B$1-J5-U5-V5 -> -1868.48 | AC5: =AB5/T5/$B$1 -> #DIV/0! | AD5: =AB5/J5 -> #DIV/0! | AE5: =P5*(1-I5)*(1+'参数表'!$C$6)*(W5+X5+H5)*1.1+0.4*1.1 -> 0.44 | AF5: =(P5*(1-I5)*1.1+R5)*(W5+X5+H5)*1.1+0.4*1.1 -> 0.44
A6: https://www.amazon.co.jp/%E3%83%91%E3%82%A4%E3%83%AD%E3%83%83%E3%83%88-4%E8%89%B2%E3%83%9C%E3%83%BC%E3%83%AB%E3%83%9A%E3%83%B3-%E3%83%95%E3%83%AA%E3%82%AF%E3%82%B7%E3%83%A7%E3%83%B3%E3%83%9C%E3%83%BC%E3%83%AB4-LKFB-3SEF-BN-0-5mm/dp/B00IMDNQ3A?ref_=ast_sto_dp&th=1 | C6: 01-2601-0075 | D6: 4色变体 | G6: 4902505472954 | H6: 0.05 | I6: 0 | J6: 3300 | K6: 80 | L6: 34 | M6: 24 | N6: 2 | O6: =max(L6*M6*N6/8000*1000,K6) -> 204 | P6: 47.8 | Q6: {=XLOOKUP(K6/1000, '运费（邮政）'!$A$2:$A$21, '运费（邮政）'!$B$2:$B$21, "超出范围", 1)} -> 880 | R6: 18.99 | S6: =(V6+U6-Q6)/$B$1 -> 11.401507 | T6: =P6+R6 -> 66.79 | U6: {=XLOOKUP(O6/1000, '运费（橙联）'!$A$2:$A$57, '运费（橙联）'!$B$2:$B$57, "超出范围", 1)} -> 1581 | V6: =(P6*'参数表'!$C$2*(1+'参数表'!$C$3))*$B$1+'参数表'!$C$4 -> 918.01396 | W6: 0.127 | X6: 0.0135 | Y6: =(P6*(1-I6)-AE6)*$B$1-J6-Q6 -> 980.54426 | Z6: =Y6/P6/$B$1 -> 0.14446111 | AA6: =Y6/J6 -> 0.29713462 | AB6: =(P6*(1-I6)+R6-AF6)*$B$1-J6-U6-V6 -> 1493.042 | AC6: =AB6/T6/$B$1 -> 0.15742447 | AD6: =AB6/J6 -> 0.45243696 | AE6: =P6*(1-I6)*(1+'参数表'!$C$6)*(W6+X6+H6)*1.1+0.4*1.1 -> 11.458139 | AF6: =(P6*(1-I6)*1.1+R6)*(W6+X6+H6)*1.1+0.4*1.1 -> 15.437494
A7: https://www.amazon.co.jp/%E3%83%A6%E3%83%BC%E3%82%A8%E3%83%A0%E5%B7%A5%E6%A5%AD-403-50-%E3%82%B7%E3%83%AB%E3%82%AD%E3%83%BC-%E3%82%AB%E3%82%BF%E3%83%8A%E3%83%9C%E3%83%BC%E3%82%A4-500mm/dp/B002GKB5PQ/ref=zg_bs_g_2039536051_d_sccl_12/357-9393567-9939435?psc=1 | C7: 01-2601-0076 | D7: 重复 | G7: 7241870617544 | H7: 0.05 | I7: 0 | J7: 10129 | K7: 1880 | L7: 125 | M7: 16.5 | N7: 4.5 | O7: =max(L7*M7*N7/8000*1000,K7) -> 1880 | P7: 158 | Q7: {=XLOOKUP(K7/1000, '运费（邮政）'!$A$2:$A$21, '运费（邮政）'!$B$2:$B$21, "超出范围", 1)} -> 4120 | R7: 34.99 | S7: =(V7+U7-Q7)/$B$1 -> 16.702223 | T7: =P7+R7 -> 192.99 | U7: {=XLOOKUP(O7/1000, '运费（橙联）'!$A$2:$A$57, '运费（橙联）'!$B$2:$B$57, "超出范围", 1)} -> 3976 | V7: =(P7*'参数表'!$C$2*(1+'参数表'!$C$3))*$B$1+'参数表'!$C$4 -> 2515.7156 | W7: 0.127 | X7: 0.0135 | Y7: =(P7*(1-I7)-AE7)*$B$1-J7-Q7 -> 2952.9098 | Z7: =Y7/P7/$B$1 -> 0.13161481 | AA7: =Y7/J7 -> 0.29153024 | AB7: =(P7*(1-I7)+R7-AF7)*$B$1-J7-U7-V7 -> 4508.6083 | AC7: =AB7/T7/$B$1 -> 0.16452025 | AD7: =AB7/J7 -> 0.4451188 | AE7: =P7*(1-I7)*(1+'参数表'!$C$6)*(W7+X7+H7)*1.1+0.4*1.1 -> 36.85979 | AF7: =(P7*(1-I7)*1.1+R7)*(W7+X7+H7)*1.1+0.4*1.1 -> 44.191944
A8: https://www.amazon.co.jp/PILOT-%E3%83%9C%E3%83%BC%E3%83%AB%E3%83%9A%E3%83%B3-%E3%83%95%E3%83%AA%E3%82%AF%E3%82%B7%E3%83%A7%E3%83%B3%E3%83%9C%E3%83%BC%E3%83%AB%E3%83%8E%E3%83%83%E3%82%AF%E3%82%BE%E3%83%BC%E3%83%B3-%E3%82%A4%E3%83%B3%E3%82%B9%E3%83%94%E3%83%AC%E3%83%BC%E3%82%B7%E3%83%A7%E3%83%B3%E3%83%AC%E3%83%83%E3%83%89-LFBKZ3SEFIR/dp/B0BMZT54C5?ref_=ast_sto_dp&th=1 | C8: 01-2601-0078 | G8: 4902505652134 | H8: 0.05 | I8: 0 | J8: 3300 | K8: 80 | L8: 34 | M8: 24 | N8: 2 | O8: =max(L8*M8*N8/8000*1000,K8) -> 204 | P8: 47.8 | Q8: {=XLOOKUP(K8/1000, '运费（邮政）'!$A$2:$A$21, '运费（邮政）'!$B$2:$B$21, "超出范围", 1)} -> 880 | R8: 18.99 | S8: =(V8+U8-Q8)/$B$1 -> 11.401507 | T8: =P8+R8 -> 66.79 | U8: {=XLOOKUP(O8/1000, '运费（橙联）'!$A$2:$A$57, '运费（橙联）'!$B$2:$B$57, "超出范围", 1)} -> 1581 | V8: =(P8*'参数表'!$C$2*(1+'参数表'!$C$3))*$B$1+'参数表'!$C$4 -> 918.01396 | W8: 0.127 | X8: 0.0135 | Y8: =(P8*(1-I8)-AE8)*$B$1-J8-Q8 -> 980.54426 | Z8: =Y8/P8/$B$1 -> 0.14446111 | AA8: =Y8/J8 -> 0.29713462 | AB8: =(P8*(1-I8)+R8-AF8)*$B$1-J8-U8-V8 -> 1493.042 | AC8: =AB8/T8/$B$1 -> 0.15742447 | AD8: =AB8/J8 -> 0.45243696 | AE8: =P8*(1-I8)*(1+'参数表'!$C$6)*(W8+X8+H8)*1.1+0.4*1.1 -> 11.458139 | AF8: =(P8*(1-I8)*1.1+R8)*(W8+X8+H8)*1.1+0.4*1.1 -> 15.437494
A9: https://www.amazon.co.jp/%E3%82%BC%E3%83%96%E3%83%A9-%E3%82%B8%E3%82%A7%E3%83%AB%E3%83%9C%E3%83%BC%E3%83%AB%E3%83%9A%E3%83%B3-%E3%82%B5%E3%83%A9%E3%82%B5%E3%82%AF%E3%83%AA%E3%83%83%E3%83%97-%E3%83%9E%E3%82%A4%E3%83%A1%E3%83%AD%E3%83%87%E3%82%A3%EF%BC%86%E3%82%AF%E3%83%AD%E3%83%9F-JJ15-MMKU-5C/dp/B0F2D4S99Z/ref=sr_1_10?crid=2W1ERF33UNGBZ&dib=eyJ2IjoiMSJ9.xdOQlEeBBWGFNZTSZSp1MHFgv96bUH47qxV9_U74j1A4gie8FjQlRjC6lOGbAPRoY6Mu_pXvFuN20K4E6rIGcDsFo18KNTDfKay5fAsdqtZlDnn9mU44ITQVpyKAZpA-8rZmQ_fOMMqLlyMSobRAg57lQeQjmRX6CyXRpFgu8-UrsZHsNK1ktnSZcDm_e1FQd5Q9nuvip_hQdo84M3IdgJWNrG63S63IYaAYplpKbkktql66tDBbNE__P6Vtfefomej0LYpzsvWPaPGI7KqBSNi_fidsl48U_Our9bp-v-o.RGyKS_UYKkRbuxa6axqsrlRcvU7xaNOJi8s2KNpFcek&dib_tag=se&keywords=zebra&qid=1768526158&sprefix=zebra%2Caps%2C309&sr=8-10 | C9: 01-2601-0079 | D9: 是 | G9: 4901681831463 | H9: 0.05 | I9: 0 | J9: 1106 | K9: 80 | L9: 34 | M9: 24 | N9: 2 | O9: =max(L9*M9*N9/8000*1000,K9) -> 204 | P9: 21.8 | Q9: {=XLOOKUP(K9/1000, '运费（邮政）'!$A$2:$A$21, '运费（邮政）'!$B$2:$B$21, "超出范围", 1)} -> 880 | R9: 12.99 | S9: =(V9+U9-Q9)/$B$1 -> 8.7469068 | T9: =P9+R9 -> 34.79 | U9: {=XLOOKUP(O9/1000, '运费（橙联）'!$A$2:$A$57, '运费（橙联）'!$B$2:$B$57, "超出范围", 1)} -> 1581 | V9: =(P9*'参数表'!$C$2*(1+'参数表'!$C$3))*$B$1+'参数表'!$C$4 -> 541.06076 | W9: 0.127 | X9: 0.0135 | Y9: =(P9*(1-I9)-AE9)*$B$1-J9-Q9 -> 333.56872 | Z9: =Y9/P9/$B$1 -> 0.10775576 | AA9: =Y9/J9 -> 0.30159921 | AB9: =(P9*(1-I9)+R9-AF9)*$B$1-J9-U9-V9 -> 549.55622 | AC9: =AB9/T9/$B$1 -> 0.11124215 | AD9: =AB9/J9 -> 0.49688628 | AE9: =P9*(1-I9)*(1+'参数表'!$C$6)*(W9+X9+H9)*1.1+0.4*1.1 -> 5.465009 | AF9: =(P9*(1-I9)*1.1+R9)*(W9+X9+H9)*1.1+0.4*1.1 -> 8.1870635
A10: https://www.amazon.co.jp/dp/B0FKTCF191/ref=sspa_dk_detail_1?pd_rd_i=B0FKTCF191&pd_rd_w=8EnnM&content-id=amzn1.sym.f293be60-50b7-49bc-95e8-931faf86ed1e&pf_rd_p=f293be60-50b7-49bc-95e8-931faf86ed1e&pf_rd_r=WEZ55RMBKF000HZ0BPD8&pd_rd_wg=JkCxH&pd_rd_r=b041411b-b595-4ba2-9092-601825c9e6ca&sp_csd=d2lkZ2V0TmFtZT1zcF9kZXRhaWw&th=1 | C10: 01-2601-0080 | D10: 3色变体 | G10: 4550624770859 | H10: 0.05 | I10: 0 | J10: 1210 | K10: 80 | L10: 34 | M10: 24 | N10: 2 | O10: =max(L10*M10*N10/8000*1000,K10) -> 204 | P10: 23.8 | Q10: {=XLOOKUP(K10/1000, '运费（邮政）'!$A$2:$A$21, '运费（邮政）'!$B$2:$B$21, "超出范围", 1)} -> 880 | R10: 12.99 | S10: =(V10+U10-Q10)/$B$1 -> 8.9511068 | T10: =P10+R10 -> 36.79 | U10: {=XLOOKUP(O10/1000, '运费（橙联）'!$A$2:$A$57, '运费（橙联）'!$B$2:$B$57, "超出范围", 1)} -> 1581 | V10: =(P10*'参数表'!$C$2*(1+'参数表'!$C$3))*$B$1+'参数表'!$C$4 -> 570.05716 | W10: 0.127 | X10: 0.0135 | Y10: =(P10*(1-I10)-AE10)*$B$1-J10-Q10 -> 448.1053 | Z10: =Y10/P10/$B$1 -> 0.13259122 | AA10: =Y10/J10 -> 0.37033496 | AB10: =(P10*(1-I10)+R10-AF10)*$B$1-J10-U10-V10 -> 635.0964 | AC10: =AB10/T10/$B$1 -> 0.12156863 | AD10: =AB10/J10 -> 0.52487306 | AE10: =P10*(1-I10)*(1+'参数表'!$C$6)*(W10+X10+H10)*1.1+0.4*1.1 -> 5.926019 | AF10: =(P10*(1-I10)*1.1+R10)*(W10+X10+H10)*1.1+0.4*1.1 -> 8.6480735
A11: https://www.amazon.co.jp/dp/B0FKTF2XVZ/ref=sspa_dk_detail_2?pf_rd_p=f293be60-50b7-49bc-95e8-931faf86ed1e&pf_rd_r=WEZ55RMBKF000HZ0BPD8&pd_rd_wg=JkCxH&pd_rd_w=8EnnM&content-id=amzn1.sym.f293be60-50b7-49bc-95e8-931faf86ed1e&pd_rd_r=b041411b-b595-4ba2-9092-601825c9e6ca&sp_csd=d2lkZ2V0TmFtZT1zcF9kZXRhaWw&th=1 | C11: 01-2601-0081 | D11: 同上 | H11: 0.05 | I11: 0 | L11: 34 | M11: 24 | N11: 2 | O11: =max(L11*M11*N11/8000*1000,K11) -> 204 | Q11: {=XLOOKUP(K11/1000, '运费（邮政）'!$A$2:$A$21, '运费（邮政）'!$B$2:$B$21, "超出范围", 1)} -> 880 | S11: =(V11+U11-Q11)/$B$1 -> 6.5211268 | T11: =P11+R11 -> 0 | U11: {=XLOOKUP(O11/1000, '运费（橙联）'!$A$2:$A$57, '运费（橙联）'!$B$2:$B$57, "超出范围", 1)} -> 1581 | V11: =(P11*'参数表'!$C$2*(1+'参数表'!$C$3))*$B$1+'参数表'!$C$4 -> 225 | W11: 0.127 | X11: 0.0135 | Y11: =(P11*(1-I11)-AE11)*$B$1-J11-Q11 -> -942.48 | Z11: =Y11/P11/$B$1 -> #DIV/0! | AA11: =Y11/J11 -> #DIV/0! | AB11: =(P11*(1-I11)+R11-AF11)*$B$1-J11-U11-V11 -> -1868.48 | AC11: =AB11/T11/$B$1 -> #DIV/0! | AD11: =AB11/J11 -> #DIV/0! | AE11: =P11*(1-I11)*(1+'参数表'!$C$6)*(W11+X11+H11)*1.1+0.4*1.1 -> 0.44 | AF11: =(P11*(1-I11)*1.1+R11)*(W11+X11+H11)*1.1+0.4*1.1 -> 0.44
A12: https://www.amazon.co.jp/%E3%82%BC%E3%83%96%E3%83%A9-%E3%82%B8%E3%82%A7%E3%83%AB%E3%83%9C%E3%83%BC%E3%83%AB%E3%83%9A%E3%83%B3-%E3%82%B5%E3%83%A9%E3%82%B5%E3%82%AF%E3%83%AA%E3%83%83%E3%83%97-0-5mm-JJ29-KF-5C/dp/B0DYJQ5GLH/ref=pd_ci_mcx_pspc_dp_d_2_t_3?pd_rd_w=9PcBC&content-id=amzn1.sym.8f1fe2a7-d128-4328-bcac-c2e341dfd86d%3Aamzn1.symc.8c21723d-cd1d-422f-9cc5-7a61ace3c767&pf_rd_p=8f1fe2a7-d128-4328-bcac-c2e341dfd86d&pf_rd_r=WEZ55RMBKF000HZ0BPD8&pd_rd_wg=JkCxH&pd_rd_r=b041411b-b595-4ba2-9092-601825c9e6ca&pd_rd_i=B0DYJQ5GLH | C12: 01-2601-0082 | D12: 是 | G12: 4901681818464 | H12: 0.05 | I12: 0 | J12: 900 | K12: 110 | L12: 34 | M12: 24 | N12: 2 | O12: =max(L12*M12*N12/8000*1000,K12) -> 204 | P12: 21.8 | Q12: {=XLOOKUP(K12/1000, '运费（邮政）'!$A$2:$A$21, '运费（邮政）'!$B$2:$B$21, "超出范围", 1)} -> 1060 | R12: 12.99 | S12: =(V12+U12-Q12)/$B$1 -> 7.4793011 | T12: =P12+R12 -> 34.79 | U12: {=XLOOKUP(O12/1000, '运费（橙联）'!$A$2:$A$57, '运费（橙联）'!$B$2:$B$57, "超出范围", 1)} -> 1581 | V12: =(P12*'参数表'!$C$2*(1+'参数表'!$C$3))*$B$1+'参数表'!$C$4 -> 541.06076 | W12: 0.127 | X12: 0.0135 | Y12: =(P12*(1-I12)-AE12)*$B$1-J12-Q12 -> 359.56872 | Z12: =Y12/P12/$B$1 -> 0.11615478 | AA12: =Y12/J12 -> 0.3995208 | AB12: =(P12*(1-I12)+R12-AF12)*$B$1-J12-U12-V12 -> 755.55622 | AC12: =AB12/T12/$B$1 -> 0.15294103 | AD12: =AB12/J12 -> 0.83950691 | AE12: =P12*(1-I12)*(1+'参数表'!$C$6)*(W12+X12+H12)*1.1+0.4*1.1 -> 5.465009 | AF12: =(P12*(1-I12)*1.1+R12)*(W12+X12+H12)*1.1+0.4*1.1 -> 8.1870635
A13: https://www.amazon.co.jp/%E3%82%BC%E3%83%96%E3%83%A9-%E3%82%B8%E3%82%A7%E3%83%AB%E3%83%9C%E3%83%BC%E3%83%AB%E3%83%9A%E3%83%B3-%E3%82%B5%E3%83%A9%E3%82%B5%E3%82%AF%E3%83%AA%E3%83%83%E3%83%97-%E3%83%8F%E3%83%AA%E3%83%BC%E3%83%BB%E3%83%9D%E3%83%83%E3%82%BF%E3%83%BC-JJ29-HP-4C/dp/B0FXKX12T6/ref=sr_1_5?crid=20024SRCOS2XV&dib=eyJ2IjoiMSJ9.rWLJSoZyhQrM-SeYB-jDgjwm4IMaMb9JiD8j8KQqQ675-XZbLOQLgO0o4rdO4tMaLSVuBNapfEy287eo6kgFc5GW-KwW_VOaDp3yOKVCUh2NnX1h7JtFx8R0bko_R4-eJuhCtQlcEfHldI8rhupFDIKKlnKTt2SCMZ6fkRfc2J1b_QCp2ilFB9aLMgq4--WqOXedeFFaJovdbF6A4n9nYyK7nPlkwaASrrqgH5J3F1TgfHf7YKQha5e9RUIrI-EP0jusGloMopxf910-z4BwYrUPx9i2SNyMPpYy3u2mv18.THAjTe9AVJhGKLZMZNnHyH-dl-LFpajgvif0flGeLQY&dib_tag=se&keywords=zebra+harry+potter&qid=1768526776&sprefix=zebra+ha%2Caps%2C243&sr=8-5 | C13: 01-2601-0083 | D13: 是 | G13: 4901681886388 | H13: 0.05 | I13: 0 | J13: 1350 | K13: 80 | L13: 34 | M13: 24 | N13: 2 | O13: =max(L13*M13*N13/8000*1000,K13) -> 204 | P13: 24.2 | Q13: {=XLOOKUP(K13/1000, '运费（邮政）'!$A$2:$A$21, '运费（邮政）'!$B$2:$B$21, "超出范围", 1)} -> 880 | R13: 12.99 | S13: =(V13+U13-Q13)/$B$1 -> 8.9919468 | T13: =P13+R13 -> 37.19 | U13: {=XLOOKUP(O13/1000, '运费（橙联）'!$A$2:$A$57, '运费（橙联）'!$B$2:$B$57, "超出范围", 1)} -> 1581 | V13: =(P13*'参数表'!$C$2*(1+'参数表'!$C$3))*$B$1+'参数表'!$C$4 -> 575.85644 | W13: 0.127 | X13: 0.0135 | Y13: =(P13*(1-I13)-AE13)*$B$1-J13-Q13 -> 351.81262 | Z13: =Y13/P13/$B$1 -> 0.10237825 | AA13: =Y13/J13 -> 0.26060194 | AB13: =(P13*(1-I13)+R13-AF13)*$B$1-J13-U13-V13 -> 533.00444 | AC13: =AB13/T13/$B$1 -> 0.10092908 | AD13: =AB13/J13 -> 0.3948181 | AE13: =P13*(1-I13)*(1+'参数表'!$C$6)*(W13+X13+H13)*1.1+0.4*1.1 -> 6.018221 | AF13: =(P13*(1-I13)*1.1+R13)*(W13+X13+H13)*1.1+0.4*1.1 -> 8.7402755
A14: https://www.amazon.co.jp/Piececool-%E7%AB%8B%E4%BD%93%E3%83%91%E3%82%BA%E3%83%AB-%E3%83%A1%E3%82%BF%E3%83%AA%E3%83%83%E3%82%AF%E3%83%8A%E3%83%8E%E3%83%91%E3%82%BA%E3%83%AB-%E3%83%95%E3%83%A9%E3%82%A4%E3%83%B3%E3%82%B0%E3%83%BB%E3%83%80%E3%83%83%E3%83%81%E3%83%9E%E3%83%B3-%E3%82%A2%E3%83%83%E3%83%97%E3%82%B0%E3%83%AC%E3%83%BC%E3%83%89%E7%89%88/dp/B09YT1YSKB/ref=sr_1_59?crid=17D3QITS52M7D&dib=eyJ2IjoiMSJ9.olFbl_N22_DSrBlzMUCjMq1ClVmhyqD1jMvs2qKqIebSN2N1uWOJ0dXNw42MNMYKofI-SfhEypjObxqVlvTzAcnnqodHunxfilePYLilXjrib31J56p_uXdQiMPY8vF6LAiGScN24REfB2-wdseiwkqKDmgdmsNlFPWsNV5Lwi7i8SXzbNM5wuo0StZLfL_396hBzKKwd8y_9VOq3yH5r37o_DxYoss5bt67epn-RnRD2INeKYl3P6RUkAGSFQBOKBLA_-wjtmb3BUE4599h9RJJBta-RY065r2I4cDmfL4.VyZo6BC8MPrp8P3xIqarBkd3QU84UKDT4w1mCiNXlPw&dib_tag=se&keywords=rokr&qid=1768526854&sprefix=rokr%2Caps%2C329&sr=8-59&th=1 | C14: 01-2601-0084 | H14: 0.05 | I14: 0 | J14: 4980 | K14: 410 | L14: 34 | M14: 24 | N14: 2 | O14: =max(L14*M14*N14/8000*1000,K14) -> 410 | P14: 74.8 | Q14: {=XLOOKUP(K14/1000, '运费（邮政）'!$A$2:$A$21, '运费（邮政）'!$B$2:$B$21, "超出范围", 1)} -> 1600 | R14: 21.99 | S14: =(V14+U14-Q14)/$B$1 -> 12.461024 | T14: =P14+R14 -> 96.79 | U14: {=XLOOKUP(O14/1000, '运费（橙联）'!$A$2:$A$57, '运费（橙联）'!$B$2:$B$57, "超出范围", 1)} -> 2060 | V14: =(P14*'参数表'!$C$2*(1+'参数表'!$C$3))*$B$1+'参数表'!$C$4 -> 1309.4654 | W14: 0.127 | X14: 0.0135 | Y14: =(P14*(1-I14)-AE14)*$B$1-J14-Q14 -> 1530.7881 | Z14: =Y14/P14/$B$1 -> 0.14412029 | AA14: =Y14/J14 -> 0.30738717 | AB14: =(P14*(1-I14)+R14-AF14)*$B$1-J14-U14-V14 -> 2229.5661 | AC14: =AB14/T14/$B$1 -> 0.16221892 | AD14: =AB14/J14 -> 0.44770403 | AE14: =P14*(1-I14)*(1+'参数表'!$C$6)*(W14+X14+H14)*1.1+0.4*1.1 -> 17.681774 | AF14: =(P14*(1-I14)*1.1+R14)*(W14+X14+H14)*1.1+0.4*1.1 -> 22.289779
A15: https://www.amazon.co.jp/LQHZC%E2%80%8B-%E6%8A%98%E7%95%B3%E3%81%AE%E3%81%93%E3%81%8E%E3%82%8A-%E9%BB%92%E3%83%81%E3%82%BF%E3%83%B3%E3%82%B3%E3%83%BC%E3%83%86%E3%82%A3%E3%83%B3%E3%82%B0-%E5%AE%89%E5%85%A8%E3%83%AD%E3%83%83%E3%82%AF%E4%BB%98%E3%81%8D-%E6%BB%91%E3%82%8A%E6%AD%A2%E3%82%81%E3%82%B0%E3%83%AA%E3%83%83%E3%83%97/dp/B0FP5K8HJB/ref=zg_bs_g_2039536051_d_sccl_14/357-9393567-9939435?th=1 | C15: 01-2601-0085 | D15: 是 | G15: 0769016152157 | H15: 0.05 | I15: 0 | J15: 1399 | K15: 310 | L15: 34 | M15: 24 | N15: 2 | O15: =max(L15*M15*N15/8000*1000,K15) -> 310 | P15: 29.8 | Q15: {=XLOOKUP(K15/1000, '运费（邮政）'!$A$2:$A$21, '运费（邮政）'!$B$2:$B$21, "超出范围", 1)} -> 1420 | R15: 12.99 | S15: =(V15+U15-Q15)/$B$1 -> 7.1482138 | T15: =P15+R15 -> 42.79 | U15: {=XLOOKUP(O15/1000, '运费（橙联）'!$A$2:$A$57, '运费（橙联）'!$B$2:$B$57, "超出范围", 1)} -> 1778 | V15: =(P15*'参数表'!$C$2*(1+'参数表'!$C$3))*$B$1+'参数表'!$C$4 -> 657.04636 | W15: 0.127 | X15: 0.0135 | Y15: =(P15*(1-I15)-AE15)*$B$1-J15-Q15 -> 374.71504 | Z15: =Y15/P15/$B$1 -> 0.088551622 | AA15: =Y15/J15 -> 0.26784492 | AB15: =(P15*(1-I15)+R15-AF15)*$B$1-J15-U15-V15 -> 817.71694 | AC15: =AB15/T15/$B$1 -> 0.13457747 | AD15: =AB15/J15 -> 0.58450103 | AE15: =P15*(1-I15)*(1+'参数表'!$C$6)*(W15+X15+H15)*1.1+0.4*1.1 -> 7.309049 | AF15: =(P15*(1-I15)*1.1+R15)*(W15+X15+H15)*1.1+0.4*1.1 -> 10.031104
A16: https://www.amazon.co.jp/%E3%83%8F%E3%83%8A%E3%83%A4%E3%83%9E-%E3%81%AF%E3%81%9A%E3%82%8B-%E3%82%BC%E3%83%AB%E3%83%80%E3%81%AE%E4%BC%9D%E8%AA%AC-%E3%83%9E%E3%82%B9%E3%82%BF%E3%83%BC%E3%82%BD%E3%83%BC%E3%83%89-075695/dp/B0BVXXJ38P/ref=zg_bs_g_2189598051_d_sccl_7/355-3582507-3163057?th=1 | C16: 01-2601-0086 | D16: 是 | G16: 4977513075695 | H16: 0.05 | I16: 0 | J16: 3300 | K16: 210 | L16: 34 | M16: 24 | N16: 2 | O16: =max(L16*M16*N16/8000*1000,K16) -> 210 | P16: 49.8 | Q16: {=XLOOKUP(K16/1000, '运费（邮政）'!$A$2:$A$21, '运费（邮政）'!$B$2:$B$21, "超出范围", 1)} -> 1240 | R16: 15.99 | S16: =(V16+U16-Q16)/$B$1 -> 9.0704955 | T16: =P16+R16 -> 65.79 | U16: {=XLOOKUP(O16/1000, '运费（橙联）'!$A$2:$A$57, '运费（橙联）'!$B$2:$B$57, "超出范围", 1)} -> 1581 | V16: =(P16*'参数表'!$C$2*(1+'参数表'!$C$3))*$B$1+'参数表'!$C$4 -> 947.01036 | W16: 0.127 | X16: 0.0135 | Y16: =(P16*(1-I16)-AE16)*$B$1-J16-Q16 -> 839.08084 | Z16: =Y16/P16/$B$1 -> 0.11865502 | AA16: =Y16/J16 -> 0.25426692 | AB16: =(P16*(1-I16)+R16-AF16)*$B$1-J16-U16-V16 -> 1345.8504 | AC16: =AB16/T16/$B$1 -> 0.14406171 | AD16: =AB16/J16 -> 0.40783347 | AE16: =P16*(1-I16)*(1+'参数表'!$C$6)*(W16+X16+H16)*1.1+0.4*1.1 -> 11.919149 | AF16: =(P16*(1-I16)*1.1+R16)*(W16+X16+H16)*1.1+0.4*1.1 -> 15.269853
A17: https://www.amazon.co.jp/%E3%83%8F%E3%83%8A%E3%83%A4%E3%83%9E-HANAYAMA-%E3%82%AF%E3%83%AA%E3%82%B9%E3%82%BF%E3%83%AB%E3%82%AE%E3%83%A3%E3%83%A9%E3%83%AA%E3%83%BC-%E3%83%8F%E3%83%AD%E3%83%BC%E3%82%AD%E3%83%86%E3%82%A3/dp/B07FGSQT2J/ref=zg_bs_g_2189598051_d_sccl_16/355-3582507-3163057?th=1 | C17: 01-2601-0087 | D17: 是 | G17: 4977513076289 | H17: 0.05 | I17: 0 | J17: 1309 | K17: 210 | L17: 15 | M17: 5 | N17: 10 | O17: =max(L17*M17*N17/8000*1000,K17) -> 210 | P17: 27.9 | Q17: {=XLOOKUP(K17/1000, '运费（邮政）'!$A$2:$A$21, '运费（邮政）'!$B$2:$B$21, "超出范围", 1)} -> 1240 | R17: 12.99 | S17: =(V17+U17-Q17)/$B$1 -> 6.8345055 | T17: =P17+R17 -> 40.89 | U17: {=XLOOKUP(O17/1000, '运费（橙联）'!$A$2:$A$57, '运费（橙联）'!$B$2:$B$57, "超出范围", 1)} -> 1581 | V17: =(P17*'参数表'!$C$2*(1+'参数表'!$C$3))*$B$1+'参数表'!$C$4 -> 629.49978 | W17: 0.127 | X17: 0.0135 | Y17: =(P17*(1-I17)-AE17)*$B$1-J17-Q17 -> 437.10529 | Z17: =Y17/P17/$B$1 -> 0.11032997 | AA17: =Y17/J17 -> 0.33392306 | AB17: =(P17*(1-I17)+R17-AF17)*$B$1-J17-U17-V17 -> 924.65377 | AC17: =AB17/T17/$B$1 -> 0.15924789 | AD17: =AB17/J17 -> 0.7063818 | AE17: =P17*(1-I17)*(1+'参数表'!$C$6)*(W17+X17+H17)*1.1+0.4*1.1 -> 6.8710895 | AF17: =(P17*(1-I17)*1.1+R17)*(W17+X17+H17)*1.1+0.4*1.1 -> 9.593144
A18: https://www.amazon.co.jp/FUNPOLA-%E3%83%99%E3%83%8D%E3%83%81%E3%82%A2%E3%81%AE%E6%98%9F-Booknook-LED%E3%83%A9%E3%82%A4%E3%83%88%E4%BB%98%E3%81%8D-%E5%88%9D%E5%BF%83%E8%80%85%E3%82%84%E4%B8%AD%E5%AD%A6%E7%94%9F%E5%90%91%E3%81%91/dp/B0FZ2QTRH1/ref=zg_bs_g_2189598051_d_sccl_33/355-3582507-3163057?th=1 | C18: 01-2601-0088 | D18: 4变体 | H18: 0.05 | I18: 0 | J18: 7980 | K18: 1210 | L18: 26 | M18: 16 | N18: 0.1 | O18: =max(L18*M18*N18/8000*1000,K18) -> 1210 | P18: 129 | Q18: {=XLOOKUP(K18/1000, '运费（邮政）'!$A$2:$A$21, '运费（邮政）'!$B$2:$B$21, "超出范围", 1)} -> 3040 | R18: 29.99 | S18: =(V18+U18-Q18)/$B$1 -> 17.051182 | T18: =P18+R18 -> 158.99 | U18: {=XLOOKUP(O18/1000, '运费（橙联）'!$A$2:$A$57, '运费（橙联）'!$B$2:$B$57, "超出范围", 1)} -> 3366 | V18: =(P18*'参数表'!$C$2*(1+'参数表'!$C$3))*$B$1+'参数表'!$C$4 -> 2095.2678 | W18: 0.127 | X18: 0.0135 | Y18: =(P18*(1-I18)-AE18)*$B$1-J18-Q18 -> 3013.1294 | Z18: =Y18/P18/$B$1 -> 0.16449009 | AA18: =Y18/J18 -> 0.37758514 | AB18: =(P18*(1-I18)+R18-AF18)*$B$1-J18-U18-V18 -> 3958.0562 | AC18: =AB18/T18/$B$1 -> 0.17531691 | AD18: =AB18/J18 -> 0.49599701 | AE18: =P18*(1-I18)*(1+'参数表'!$C$6)*(W18+X18+H18)*1.1+0.4*1.1 -> 30.175145 | AF18: =(P18*(1-I18)*1.1+R18)*(W18+X18+H18)*1.1+0.4*1.1 -> 36.45955
A19: https://www.amazon.co.jp/dp/B0G6MF8H65?tag=webspire_new-22&linkCode=osi&th=1&psc=1 | C19: 01-2601-0089 | D19: 0101重复 | H19: 0.05 | I19: 0 | L19: 34 | M19: 24 | N19: 2 | O19: =max(L19*M19*N19/8000*1000,K19) -> 204 | Q19: {=XLOOKUP(K19/1000, '运费（邮政）'!$A$2:$A$21, '运费（邮政）'!$B$2:$B$21, "超出范围", 1)} -> 880 | S19: =(V19+U19-Q19)/$B$1 -> 6.5211268 | T19: =P19+R19 -> 0 | U19: {=XLOOKUP(O19/1000, '运费（橙联）'!$A$2:$A$57, '运费（橙联）'!$B$2:$B$57, "超出范围", 1)} -> 1581 | V19: =(P19*'参数表'!$C$2*(1+'参数表'!$C$3))*$B$1+'参数表'!$C$4 -> 225 | W19: 0.127 | X19: 0.0135 | Y19: =(P19*(1-I19)-AE19)*$B$1-J19-Q19 -> -942.48 | Z19: =Y19/P19/$B$1 -> #DIV/0! | AA19: =Y19/J19 -> #DIV/0! | AB19: =(P19*(1-I19)+R19-AF19)*$B$1-J19-U19-V19 -> -1868.48 | AC19: =AB19/T19/$B$1 -> #DIV/0! | AD19: =AB19/J19 -> #DIV/0! | AE19: =P19*(1-I19)*(1+'参数表'!$C$6)*(W19+X19+H19)*1.1+0.4*1.1 -> 0.44 | AF19: =(P19*(1-I19)*1.1+R19)*(W19+X19+H19)*1.1+0.4*1.1 -> 0.44
A20: https://www.amazon.co.jp/%E7%9F%B3%E9%8B%B8%E5%B7%A5%E6%A5%AD-%E7%8F%BE%E5%A0%B4%E5%B1%8B-%E3%82%B1%E3%83%BC%E3%82%B9%E4%BB%98%E6%9E%9D%E5%88%87%E9%8B%B8-135mm/dp/B006QH7WI4/ref=zg_bs_g_2039536051_d_sccl_19/357-9393567-9939435?psc=1 | C20: 01-2601-0090 | D20: 是 | G20: 4931025006042 | H20: 0.05 | I20: 0 | J20: 961 | K20: 150 | L20: 34 | M20: 24 | N20: 2 | O20: =max(L20*M20*N20/8000*1000,K20) -> 204 | P20: 21.8 | Q20: {=XLOOKUP(K20/1000, '运费（邮政）'!$A$2:$A$21, '运费（邮政）'!$B$2:$B$21, "超出范围", 1)} -> 1060 | R20: 12.99 | S20: =(V20+U20-Q20)/$B$1 -> 7.4793011 | T20: =P20+R20 -> 34.79 | U20: {=XLOOKUP(O20/1000, '运费（橙联）'!$A$2:$A$57, '运费（橙联）'!$B$2:$B$57, "超出范围", 1)} -> 1581 | V20: =(P20*'参数表'!$C$2*(1+'参数表'!$C$3))*$B$1+'参数表'!$C$4 -> 541.06076 | W20: 0.127 | X20: 0.0135 | Y20: =(P20*(1-I20)-AE20)*$B$1-J20-Q20 -> 298.56872 | Z20: =Y20/P20/$B$1 -> 0.096449387 | AA20: =Y20/J20 -> 0.31068545 | AB20: =(P20*(1-I20)+R20-AF20)*$B$1-J20-U20-V20 -> 694.55622 | AC20: =AB20/T20/$B$1 -> 0.1405933 | AD20: =AB20/J20 -> 0.72274321 | AE20: =P20*(1-I20)*(1+'参数表'!$C$6)*(W20+X20+H20)*1.1+0.4*1.1 -> 5.465009 | AF20: =(P20*(1-I20)*1.1+R20)*(W20+X20+H20)*1.1+0.4*1.1 -> 8.1870635
A21: https://www.amazon.co.jp/%E3%82%B8%E3%82%B0%E3%82%BD%E3%83%BC%E3%83%91%E3%82%BA%E3%83%AB-%E3%82%A2%E3%83%8B%E3%83%A1%E3%80%8C%E9%AC%BC%E6%BB%85%E3%81%AE%E5%88%83%E3%80%8D-vol-1-300%E3%83%94%E3%83%BC%E3%82%B9-300-3186/dp/B0FW4R5PDJ/ref=sr_1_4_sspa?crid=165EDGQ6XKBBE&dib=eyJ2IjoiMSJ9.YiLAjQwn9kFGR8qJjXztVneWwv3vFoPSoZJQY0-BNUxnbvPHxIh4GCoedgDs2HntfZSBIMksl_HVw24kClhiBsg1vn4u01nLnq7oTloP62CAqmTL0it_frAXJ-Ul1aEcy34QXAjDAvRPQjcdgKmCEV9v1vj4NSVdEyHsgbLdoA-5N0S6uzgyiG8amcJ7hP-GFZa3dW3CgTEDFgbm56hQVP_RIRPNQekWnCC76hZaFRzFC5rtm3Jhj_QOYP1gnaoKxQvNFwrmqJ9GRI7oUgMLpzjPyuTWEE3UMHpTY6WVBs8.zVWUgCrcFwEIEQxbUGnEiXlTAmjsDIWCdby-236Jku0&dib_tag=se&keywords=%E9%AC%BC%E7%81%AD%E4%B9%8B%E5%88%83%E6%8B%BC%E5%9B%BE&qid=1768528730&refinements=p_123%3A311243&rnid=23341432051&sprefix=%E9%AC%BC%E7%81%AD%E4%B9%8B%E5%88%83%2Caps%2C234&sr=8-4-spons&sp_csd=d2lkZ2V0TmFtZT1zcF9hdGY&psc=1 | C21: 01-2601-0091 | D21: 是 | G21: 4970381529277 | H21: 0.05 | I21: 0 | J21: 1980 | K21: 210 | L21: 34 | M21: 24 | N21: 2 | O21: =max(L21*M21*N21/8000*1000,K21) -> 210 | P21: 37.9 | Q21: {=XLOOKUP(K21/1000, '运费（邮政）'!$A$2:$A$21, '运费（邮政）'!$B$2:$B$21, "超出范围", 1)} -> 1240 | R21: 12.99 | S21: =(V21+U21-Q21)/$B$1 -> 7.8555055 | T21: =P21+R21 -> 50.89 | U21: {=XLOOKUP(O21/1000, '运费（橙联）'!$A$2:$A$57, '运费（橙联）'!$B$2:$B$57, "超出范围", 1)} -> 1581 | V21: =(P21*'参数表'!$C$2*(1+'参数表'!$C$3))*$B$1+'参数表'!$C$4 -> 774.48178 | W21: 0.127 | X21: 0.0135 | Y21: =(P21*(1-I21)-AE21)*$B$1-J21-Q21 -> 858.78819 | Z21: =Y21/P21/$B$1 -> 0.15957267 | AA21: =Y21/J21 -> 0.43373141 | AB21: =(P21*(1-I21)+R21-AF21)*$B$1-J21-U21-V21 -> 1201.3547 | AC21: =AB21/T21/$B$1 -> 0.16624571 | AD21: =AB21/J21 -> 0.60674478 | AE21: =P21*(1-I21)*(1+'参数表'!$C$6)*(W21+X21+H21)*1.1+0.4*1.1 -> 9.1761395 | AF21: =(P21*(1-I21)*1.1+R21)*(W21+X21+H21)*1.1+0.4*1.1 -> 11.898194
A22: https://www.amazon.co.jp/%E8%91%AC%E9%80%81%E3%81%AE%E3%83%95%E3%83%AA%E3%83%BC%E3%83%AC%E3%83%B3-%E3%82%B9%E3%83%86%E3%83%83%E3%82%AB%E3%83%BC-PVC%E6%9D%90%E8%B3%AA-%E9%98%B2%E6%B0%B4%E3%82%B9%E3%83%86%E3%83%83%E3%82%AB%E3%83%BC-%E3%82%B3%E3%83%AC%E3%82%AF%E3%82%B7%E3%83%A7%E3%83%B3/dp/B0GDXFZ223/ref=sr_1_48?crid=9RQITUICNZMP&dib=eyJ2IjoiMSJ9.gmhCn42Cwma9VBqwd0YM5iLXIiO3XqOibqPDLPfWMqYLHALkJDF1-QLotnmIhz9dsXCdnV-2EGbvw0k-OJDMQ7aJ-x5ir0a7gWebKZwUn8oGQluHNGYBHAdqbfCxGxxmr21VNFlE63JIPaLUykubsRw0xK6E5DDSZn-1lSyPGC1Y18juas1DUNlXdjyhIFqC2Em5zNcrviogEDbzGw6jpqF-VPO2TxbMGY_CxkmOe9PcA_1xXgZY7_zhdJJrjAQilQP07bpkhrn7ZYSiICrWBwP2w4RXNSy24-Wbzbr3MsY.i88_sojIt4lnsnshJH_tXbBiSZ3kCw0bLcphOWllfrs&dib_tag=se&keywords=%E8%91%AC%E9%80%81%E3%81%AE%E3%83%95%E3%83%AA%E3%83%BC%E3%83%AC%E3%83%B3%2B%E6%8B%BC%E5%9B%BE&qid=1768529071&sprefix=%E3%82%B8%E3%82%B0%E3%82%BD%E3%83%BC%E3%83%91%E3%82%BA%E3%83%AB%2B%E8%91%AC%E9%80%81%E3%81%AE%E3%83%95%E3%83%AA%E3%83%BC%E3%83%AC%E3%83%B3%2B%E6%8B%BC%E5%9B%BE%2Caps%2C412&sr=8-48&th=1 | C22: 01-2601-0092 | D22: 是 | G22: 4977389281107 | H22: 0.05 | I22: 0 | J22: 1900 | K22: 380 | L22: 34 | M22: 24 | N22: 2 | O22: =max(L22*M22*N22/8000*1000,K22) -> 380 | P22: 37.8 | Q22: {=XLOOKUP(K22/1000, '运费（邮政）'!$A$2:$A$21, '运费（邮政）'!$B$2:$B$21, "超出范围", 1)} -> 1420 | R22: 12.99 | S22: =(V22+U22-Q22)/$B$1 -> 7.9650138 | T22: =P22+R22 -> 50.79 | U22: {=XLOOKUP(O22/1000, '运费（橙联）'!$A$2:$A$57, '运费（橙联）'!$B$2:$B$57, "超出范围", 1)} -> 1778 | V22: =(P22*'参数表'!$C$2*(1+'参数表'!$C$3))*$B$1+'参数表'!$C$4 -> 773.03196 | W22: 0.127 | X22: 0.0135 | Y22: =(P22*(1-I22)-AE22)*$B$1-J22-Q22 -> 747.86136 | Z22: =Y22/P22/$B$1 -> 0.13932882 | AA22: =Y22/J22 -> 0.39361124 | AB22: =(P22*(1-I22)+R22-AF22)*$B$1-J22-U22-V22 -> 1074.8777 | AC22: =AB22/T22/$B$1 -> 0.14903644 | AD22: =AB22/J22 -> 0.56572509 | AE22: =P22*(1-I22)*(1+'参数表'!$C$6)*(W22+X22+H22)*1.1+0.4*1.1 -> 9.153089 | AF22: =(P22*(1-I22)*1.1+R22)*(W22+X22+H22)*1.1+0.4*1.1 -> 11.875144
A23: https://www.amazon.co.jp/%E8%91%AC%E9%80%81%E3%81%AE%E3%83%95%E3%83%AA%E3%83%BC%E3%83%AC%E3%83%B3-%E3%82%AD%E3%83%A3%E3%83%A9%E3%82%AF%E3%82%BF%E3%83%BC%E3%82%B7%E3%83%BC%E3%83%B3%E3%82%BA-%EF%BC%8850%C3%9775cm%EF%BC%89-12-615s-EPOCH/dp/B0CT2FS17Z/ref=pd_day0_d_sccl_2_2/355-3582507-3163057?pd_rd_w=E5TOr&content-id=amzn1.sym.3e742e38-2b5e-4207-a2c9-5d5409d6c433&pf_rd_p=3e742e38-2b5e-4207-a2c9-5d5409d6c433&pf_rd_r=ACGNXG0AFMGZJFF534WD&pd_rd_wg=BwNVH&pd_rd_r=9bde88e4-1f43-4604-8063-bc6090dcd6b9&pd_rd_i=B0D9PXHPBK&th=1 | C23: 01-2601-0093 | D23: 是 | G23: 4977389281169 | H23: 0.05 | I23: 0 | J23: 1900 | K23: 380 | L23: 34 | M23: 24 | N23: 2 | O23: =max(L23*M23*N23/8000*1000,K23) -> 380 | P23: 37.8 | Q23: {=XLOOKUP(K23/1000, '运费（邮政）'!$A$2:$A$21, '运费（邮政）'!$B$2:$B$21, "超出范围", 1)} -> 1420 | R23: 12.99 | S23: =(V23+U23-Q23)/$B$1 -> 7.9650138 | T23: =P23+R23 -> 50.79 | U23: {=XLOOKUP(O23/1000, '运费（橙联）'!$A$2:$A$57, '运费（橙联）'!$B$2:$B$57, "超出范围", 1)} -> 1778 | V23: =(P23*'参数表'!$C$2*(1+'参数表'!$C$3))*$B$1+'参数表'!$C$4 -> 773.03196 | W23: 0.127 | X23: 0.0135 | Y23: =(P23*(1-I23)-AE23)*$B$1-J23-Q23 -> 747.86136 | Z23: =Y23/P23/$B$1 -> 0.13932882 | AA23: =Y23/J23 -> 0.39361124 | AB23: =(P23*(1-I23)+R23-AF23)*$B$1-J23-U23-V23 -> 1074.8777 | AC23: =AB23/T23/$B$1 -> 0.14903644 | AD23: =AB23/J23 -> 0.56572509 | AE23: =P23*(1-I23)*(1+'参数表'!$C$6)*(W23+X23+H23)*1.1+0.4*1.1 -> 9.153089 | AF23: =(P23*(1-I23)*1.1+R23)*(W23+X23+H23)*1.1+0.4*1.1 -> 11.875144
A24: hello kitty笔记本5set | C24: 01-2601-0094 | D24: 是 | G24: 4964694416263 | H24: 0.05 | I24: 0 | J24: 110 | K24: 30 | L24: 34 | M24: 24 | N24: 2 | O24: =max(L24*M24*N24/8000*1000,K24) -> 204 | P24: 15.43 | Q24: {=XLOOKUP(K24/1000, '运费（邮政）'!$A$2:$A$21, '运费（邮政）'!$B$2:$B$21, "超出范围", 1)} -> 880 | R24: 9.99 | S24: =(V24+U24-Q24)/$B$1 -> 8.0965298 | T24: =P24+R24 -> 25.42 | U24: {=XLOOKUP(O24/1000, '运费（橙联）'!$A$2:$A$57, '运费（橙联）'!$B$2:$B$57, "超出范围", 1)} -> 1581 | V24: =(P24*'参数表'!$C$2*(1+'参数表'!$C$3))*$B$1+'参数表'!$C$4 -> 448.70723 | W24: 0.127 | X24: 0.0135 | Y24: =(P24*(1-I24)-AE24)*$B$1-J24-Q24 -> 633.52971 | Z24: =Y24/P24/$B$1 -> 0.28914302 | AA24: =Y24/J24 -> 5.759361 | AB24: =(P24*(1-I24)+R24-AF24)*$B$1-J24-U24-V24 -> 605.13905 | AC24: =AB24/T24/$B$1 -> 0.16764526 | AD24: =AB24/J24 -> 5.5012641 | AE24: =P24*(1-I24)*(1+'参数表'!$C$6)*(W24+X24+H24)*1.1+0.4*1.1 -> 3.9966921 | AF24: =(P24*(1-I24)*1.1+R24)*(W24+X24+H24)*1.1+0.4*1.1 -> 6.0900966
A25: https://www.amazon.co.jp/dp/B07RW7KB6F?tag=webspire_new-22&linkCode=osi&th=1&psc=1 | C25: 01-2601-0095 | D25: 是 | G25: 4571164384306 | H25: 0.05 | I25: 0 | J25: 3056 | K25: 210 | L25: 14.1 | M25: 12.4 | N25: 1.3 | O25: =max(L25*M25*N25/8000*1000,K25) -> 210 | P25: 49.8 | Q25: {=XLOOKUP(K25/1000, '运费（邮政）'!$A$2:$A$21, '运费（邮政）'!$B$2:$B$21, "超出范围", 1)} -> 1240 | R25: 15.99 | S25: =(V25+U25-Q25)/$B$1 -> 9.0704955 | T25: =P25+R25 -> 65.79 | U25: {=XLOOKUP(O25/1000, '运费（橙联）'!$A$2:$A$57, '运费（橙联）'!$B$2:$B$57, "超出范围", 1)} -> 1581 | V25: =(P25*'参数表'!$C$2*(1+'参数表'!$C$3))*$B$1+'参数表'!$C$4 -> 947.01036 | W25: 0.153 | X25: 0.0135 | Y25: =(P25*(1-I25)-AE25)*$B$1-J25-Q25 -> 860.60831 | Z25: =Y25/P25/$B$1 -> 0.12169923 | AA25: =Y25/J25 -> 0.28161267 | AB25: =(P25*(1-I25)+R25-AF25)*$B$1-J25-U25-V25 -> 1302.4393 | AC25: =AB25/T25/$B$1 -> 0.13941492 | AD25: =AB25/J25 -> 0.42619088 | AE25: =P25*(1-I25)*(1+'参数表'!$C$6)*(W25+X25+H25)*1.1+0.4*1.1 -> 13.485857 | AF25: =(P25*(1-I25)*1.1+R25)*(W25+X25+H25)*1.1+0.4*1.1 -> 17.293875
A26: https://www.amazon.co.jp/dp/B0FXGS6X6V?tag=webspire_new-22&linkCode=osi&th=1&psc=1 | C26: 01-2601-0096 | D26: 是 | G26: 4527516024666 | H26: 0.05 | I26: 0 | J26: 3100 | K26: 210 | L26: 14.1 | M26: 12.4 | N26: 1.3 | O26: =max(L26*M26*N26/8000*1000,K26) -> 210 | P26: 49.8 | Q26: {=XLOOKUP(K26/1000, '运费（邮政）'!$A$2:$A$21, '运费（邮政）'!$B$2:$B$21, "超出范围", 1)} -> 1240 | R26: 15.99 | S26: =(V26+U26-Q26)/$B$1 -> 9.0704955 | T26: =P26+R26 -> 65.79 | U26: {=XLOOKUP(O26/1000, '运费（橙联）'!$A$2:$A$57, '运费（橙联）'!$B$2:$B$57, "超出范围", 1)} -> 1581 | V26: =(P26*'参数表'!$C$2*(1+'参数表'!$C$3))*$B$1+'参数表'!$C$4 -> 947.01036 | W26: 0.153 | X26: 0.0135 | Y26: =(P26*(1-I26)-AE26)*$B$1-J26-Q26 -> 816.60831 | Z26: =Y26/P26/$B$1 -> 0.11547716 | AA26: =Y26/J26 -> 0.26342203 | AB26: =(P26*(1-I26)+R26-AF26)*$B$1-J26-U26-V26 -> 1258.4393 | AC26: =AB26/T26/$B$1 -> 0.1347051 | AD26: =AB26/J26 -> 0.40594817 | AE26: =P26*(1-I26)*(1+'参数表'!$C$6)*(W26+X26+H26)*1.1+0.4*1.1 -> 13.485857 | AF26: =(P26*(1-I26)*1.1+R26)*(W26+X26+H26)*1.1+0.4*1.1 -> 17.293875
A27: https://www.amazon.co.jp/dp/B00CCTU9YY?tag=webspire_new-22&linkCode=osi&th=1&psc=1 | C27: 01-2601-0097 | D27: 是 | G27: 4988005770455 | H27: 0.05 | I27: 0 | J27: 2075 | K27: 210 | L27: 28.5 | M27: 20 | N27: 2 | O27: =max(L27*M27*N27/8000*1000,K27) -> 210 | P27: 37.9 | Q27: {=XLOOKUP(K27/1000, '运费（邮政）'!$A$2:$A$21, '运费（邮政）'!$B$2:$B$21, "超出范围", 1)} -> 1240 | R27: 12.99 | S27: =(V27+U27-Q27)/$B$1 -> 7.8555055 | T27: =P27+R27 -> 50.89 | U27: {=XLOOKUP(O27/1000, '运费（橙联）'!$A$2:$A$57, '运费（橙联）'!$B$2:$B$57, "超出范围", 1)} -> 1581 | V27: =(P27*'参数表'!$C$2*(1+'参数表'!$C$3))*$B$1+'参数表'!$C$4 -> 774.48178 | W27: 0.153 | X27: 0.0135 | Y27: =(P27*(1-I27)-AE27)*$B$1-J27-Q27 -> 594.47676 | Z27: =Y27/P27/$B$1 -> 0.11046058 | AA27: =Y27/J27 -> 0.28649483 | AB27: =(P27*(1-I27)+R27-AF27)*$B$1-J27-U27-V27 -> 884.28826 | AC27: =AB27/T27/$B$1 -> 0.12236947 | AD27: =AB27/J27 -> 0.42616301 | AE27: =P27*(1-I27)*(1+'参数表'!$C$6)*(W27+X27+H27)*1.1+0.4*1.1 -> 10.368474 | AF27: =(P27*(1-I27)*1.1+R27)*(W27+X27+H27)*1.1+0.4*1.1 -> 13.462042
A28: https://www.amazon.co.jp/dp/B0G394CNLB?tag=webspire_new-22&linkCode=osi&th=1&psc=1 | C28: 01-2601-0098 | D28: 是 | G28: 4943674435432 | H28: 0.05 | I28: 0 | J28: 2970 | K28: 210 | L28: 14.2 | M28: 12.6 | N28: 0.7 | O28: =max(L28*M28*N28/8000*1000,K28) -> 210 | P28: 49.8 | Q28: {=XLOOKUP(K28/1000, '运费（邮政）'!$A$2:$A$21, '运费（邮政）'!$B$2:$B$21, "超出范围", 1)} -> 1240 | R28: 15.99 | S28: =(V28+U28-Q28)/$B$1 -> 9.0704955 | T28: =P28+R28 -> 65.79 | U28: {=XLOOKUP(O28/1000, '运费（橙联）'!$A$2:$A$57, '运费（橙联）'!$B$2:$B$57, "超出范围", 1)} -> 1581 | V28: =(P28*'参数表'!$C$2*(1+'参数表'!$C$3))*$B$1+'参数表'!$C$4 -> 947.01036 | W28: 0.153 | X28: 0.0135 | Y28: =(P28*(1-I28)-AE28)*$B$1-J28-Q28 -> 946.60831 | Z28: =Y28/P28/$B$1 -> 0.13386056 | AA28: =Y28/J28 -> 0.31872334 | AB28: =(P28*(1-I28)+R28-AF28)*$B$1-J28-U28-V28 -> 1388.4393 | AC28: =AB28/T28/$B$1 -> 0.14862048 | AD28: =AB28/J28 -> 0.46748799 | AE28: =P28*(1-I28)*(1+'参数表'!$C$6)*(W28+X28+H28)*1.1+0.4*1.1 -> 13.485857 | AF28: =(P28*(1-I28)*1.1+R28)*(W28+X28+H28)*1.1+0.4*1.1 -> 17.293875
A29: https://www.amazon.co.jp/dp/B0FYDX6Z7D?tag=webspire_new-22&linkCode=osi&th=1&psc=1 | C29: 01-2601-0099 | D29: 是 | G29: 4571614702940 | H29: 0.05 | I29: 0 | J29: 4950 | K29: 210 | L29: 14.1 | M29: 12.4 | N29: 0.9 | O29: =max(L29*M29*N29/8000*1000,K29) -> 210 | P29: 74.8 | Q29: {=XLOOKUP(K29/1000, '运费（邮政）'!$A$2:$A$21, '运费（邮政）'!$B$2:$B$21, "超出范围", 1)} -> 1240 | R29: 21.99 | S29: =(V29+U29-Q29)/$B$1 -> 11.622995 | T29: =P29+R29 -> 96.79 | U29: {=XLOOKUP(O29/1000, '运费（橙联）'!$A$2:$A$57, '运费（橙联）'!$B$2:$B$57, "超出范围", 1)} -> 1581 | V29: =(P29*'参数表'!$C$2*(1+'参数表'!$C$3))*$B$1+'参数表'!$C$4 -> 1309.4654 | W29: 0.153 | X29: 0.0135 | Y29: =(P29*(1-I29)-AE29)*$B$1-J29-Q29 -> 1586.6326 | Z29: =Y29/P29/$B$1 -> 0.14937792 | AA29: =Y29/J29 -> 0.32053183 | AB29: =(P29*(1-I29)+R29-AF29)*$B$1-J29-U29-V29 -> 2315.1048 | AC29: =AB29/T29/$B$1 -> 0.16844255 | AD29: =AB29/J29 -> 0.46769793 | AE29: =P29*(1-I29)*(1+'参数表'!$C$6)*(W29+X29+H29)*1.1+0.4*1.1 -> 20.034982 | AF29: =(P29*(1-I29)*1.1+R29)*(W29+X29+H29)*1.1+0.4*1.1 -> 25.271901
A30: https://store.shopping.yahoo.co.jp/esdigital/10164087.html?sc_e=afvc_shp_3144472 | C30: 01-2601-0100 | D30: 是 | G30: 4560423191557 | H30: 0.05 | I30: 0 | J30: 3232 | K30: 610 | L30: 34 | M30: 24 | N30: 2 | O30: =max(L30*M30*N30/8000*1000,K30) -> 610 | P30: 58.8 | Q30: {=XLOOKUP(K30/1000, '运费（邮政）'!$A$2:$A$21, '运费（邮政）'!$B$2:$B$21, "超出范围", 1)} -> 1960 | R30: 18.99 | S30: =(V30+U30-Q30)/$B$1 -> 10.130241 | T30: =P30+R30 -> 77.79 | U30: {=XLOOKUP(O30/1000, '运费（橙联）'!$A$2:$A$57, '运费（橙联）'!$B$2:$B$57, "超出范围", 1)} -> 2321 | V30: =(P30*'参数表'!$C$2*(1+'参数表'!$C$3))*$B$1+'参数表'!$C$4 -> 1077.4942 | W30: 0.153 | X30: 0.0135 | Y30: =(P30*(1-I30)-AE30)*$B$1-J30-Q30 -> 907.81704 | Z30: =Y30/P30/$B$1 -> 0.10872581 | AA30: =Y30/J30 -> 0.28088398 | AB30: =(P30*(1-I30)+R30-AF30)*$B$1-J30-U30-V30 -> 1523.7123 | AC30: =AB30/T30/$B$1 -> 0.13794021 | AD30: =AB30/J30 -> 0.47144565 | AE30: =P30*(1-I30)*(1+'参数表'!$C$6)*(W30+X30+H30)*1.1+0.4*1.1 -> 15.843542 | AF30: =(P30*(1-I30)*1.1+R30)*(W30+X30+H30)*1.1+0.4*1.1 -> 20.366011
A31: https://www.amazon.co.jp/18%E3%82%A8%E3%82%AF%E3%82%B9%E3%83%88%E3%83%A9%E3%82%B9%E3%82%B1%E3%83%BC%E3%83%AB%E5%9B%BD%E7%94%A3%E5%90%8D%E8%BB%8A-%E5%89%B5%E5%88%8A-2026%E5%B9%B4-21-%E5%8F%B7-%E9%9B%91%E8%AA%8C/dp/B0G6MF8H65/ref=pd_sbs_d_sccl_2_3/355-3582507-3163057?pd_rd_w=eLa6J&content-id=amzn1.sym.06c48127-87ed-46e1-9c82-5caa3f707eab&pf_rd_p=06c48127-87ed-46e1-9c82-5caa3f707eab&pf_rd_r=VCMA0SBFFVJ78BS9PE9N&pd_rd_wg=RIn5r&pd_rd_r=d58db1eb-817f-4980-ab1c-c9fb6d3c9939&pd_rd_i=B0G6MF8H65&psc=1 | C31: 01-2601-0101 | D31: 是 | G31: 4912305330163 | H31: 0.05 | I31: 0 | J31: 2990 | K31: 1366 | L31: 40 | M31: 25 | N31: 15 | O31: =max(L31*M31*N31/8000*1000,K31) -> 1875 | P31: 69.8 | Q31: {=XLOOKUP(K31/1000, '运费（邮政）'!$A$2:$A$21, '运费（邮政）'!$B$2:$B$21, "超出范围", 1)} -> 3220 | R31: 25 | S31: =(V31+U31-Q31)/$B$1 -> 14.035031 | T31: =P31+R31 -> 94.8 | U31: {=XLOOKUP(O31/1000, '运费（橙联）'!$A$2:$A$57, '运费（橙联）'!$B$2:$B$57, "超出范围", 1)} -> 3976 | V31: =(P31*'参数表'!$C$2*(1+'参数表'!$C$3))*$B$1+'参数表'!$C$4 -> 1236.9744 | W31: 0.153 | X31: 0.0135 | Y31: =(P31*(1-I31)-AE31)*$B$1-J31-Q31 -> 1042.6277 | Z31: =Y31/P31/$B$1 -> 0.10519267 | AA31: =Y31/J31 -> 0.34870492 | AB31: =(P31*(1-I31)+R31-AF31)*$B$1-J31-U31-V31 -> 1754.2208 | AC31: =AB31/T31/$B$1 -> 0.13031295 | AD31: =AB31/J31 -> 0.58669594 | AE31: =P31*(1-I31)*(1+'参数表'!$C$6)*(W31+X31+H31)*1.1+0.4*1.1 -> 18.725157 | AF31: =(P31*(1-I31)*1.1+R31)*(W31+X31+H31)*1.1+0.4*1.1 -> 24.678907
A32: https://www.1101.com/store/techo/en/2026/pc/detail_toolstoys/tt_memo_okumi/ | C32: 01-2601-0102 | D32: 是 | H32: 0.05 | I32: 0 | J32: 1570 | K32: 80 | L32: 28.5 | M32: 20 | N32: 2 | O32: 2 | P32: 32.8 | Q32: {=XLOOKUP(K32/1000, '运费（邮政）'!$A$2:$A$21, '运费（邮政）'!$B$2:$B$21, "超出范围", 1)} -> 880 | R32: 12.99 | S32: =(V32+U32-Q32)/$B$1 -> 7.377049 | T32: =P32+R32 -> 45.79 | U32: {=XLOOKUP(O32/1000, '运费（橙联）'!$A$2:$A$57, '运费（橙联）'!$B$2:$B$57, "超出范围", 1)} -> 1227 | V32: =(P32*'参数表'!$C$2*(1+'参数表'!$C$3))*$B$1+'参数表'!$C$4 -> 700.54096 | W32: 0.153 | X32: 0.0135 | Y32: =(P32*(1-I32)-AE32)*$B$1-J32-Q32 -> 924.99182 | Z32: =Y32/P32/$B$1 -> 0.19859838 | AA32: =Y32/J32 -> 0.58916676 | AB32: =(P32*(1-I32)+R32-AF32)*$B$1-J32-U32-V32 -> 1282.7441 | AC32: =AB32/T32/$B$1 -> 0.19727909 | AD32: =AB32/J32 -> 0.81703448 | AE32: =P32*(1-I32)*(1+'参数表'!$C$6)*(W32+X32+H32)*1.1+0.4*1.1 -> 9.032452 | AF32: =(P32*(1-I32)*1.1+R32)*(W32+X32+H32)*1.1+0.4*1.1 -> 12.12602
A33: https://www.1101.com/store/techo/en/2026/pc/detail_toolstoys/tt_papers_okumi/ | C33: 01-2601-0103 | D33: 是 | H33: 0.05 | I33: 0 | J33: 1520 | K33: 280 | L33: 15 | M33: 10.5 | N33: 2 | O33: 2 | P33: 32.8 | Q33: {=XLOOKUP(K33/1000, '运费（邮政）'!$A$2:$A$21, '运费（邮政）'!$B$2:$B$21, "超出范围", 1)} -> 1240 | R33: 12.99 | S33: =(V33+U33-Q33)/$B$1 -> 4.8418377 | T33: =P33+R33 -> 45.79 | U33: {=XLOOKUP(O33/1000, '运费（橙联）'!$A$2:$A$57, '运费（橙联）'!$B$2:$B$57, "超出范围", 1)} -> 1227 | V33: =(P33*'参数表'!$C$2*(1+'参数表'!$C$3))*$B$1+'参数表'!$C$4 -> 700.54096 | W33: 0.127 | X33: 0.0135 | Y33: =(P33*(1-I33)-AE33)*$B$1-J33-Q33 -> 761.51991 | Z33: =Y33/P33/$B$1 -> 0.1635005 | AA33: =Y33/J33 -> 0.50099994 | AB33: =(P33*(1-I33)+R33-AF33)*$B$1-J33-U33-V33 -> 1532.0272 | AC33: =AB33/T33/$B$1 -> 0.23561747 | AD33: =AB33/J33 -> 1.0079126 | AE33: =P33*(1-I33)*(1+'参数表'!$C$6)*(W33+X33+H33)*1.1+0.4*1.1 -> 8.000564 | AF33: =(P33*(1-I33)*1.1+R33)*(W33+X33+H33)*1.1+0.4*1.1 -> 10.722618
A34: https://www.1101.com/store/techo/en/2026/pc/detail_toolstoys/tt_clearfilec_okumi/ | C34: 01-2601-0104 | D34: 是 | H34: 0.05 | I34: 0 | J34: 1520 | K34: 110 | L34: 20 | M34: 15 | N34: 0.4 | O34: =max(L34*M34*N34/8000*1000,K34) -> 110 | P34: 32.8 | Q34: {=XLOOKUP(K34/1000, '运费（邮政）'!$A$2:$A$21, '运费（邮政）'!$B$2:$B$21, "超出范围", 1)} -> 1060 | R34: 12.99 | S34: =(V34+U34-Q34)/$B$1 -> 7.0953589 | T34: =P34+R34 -> 45.79 | U34: {=XLOOKUP(O34/1000, '运费（橙联）'!$A$2:$A$57, '运费（橙联）'!$B$2:$B$57, "超出范围", 1)} -> 1367 | V34: =(P34*'参数表'!$C$2*(1+'参数表'!$C$3))*$B$1+'参数表'!$C$4 -> 700.54096 | W34: 0.127 | X34: 0.0135 | Y34: =(P34*(1-I34)-AE34)*$B$1-J34-Q34 -> 941.51991 | Z34: =Y34/P34/$B$1 -> 0.20214701 | AA34: =Y34/J34 -> 0.61942099 | AB34: =(P34*(1-I34)+R34-AF34)*$B$1-J34-U34-V34 -> 1392.0272 | AC34: =AB34/T34/$B$1 -> 0.21408623 | AD34: =AB34/J34 -> 0.91580738 | AE34: =P34*(1-I34)*(1+'参数表'!$C$6)*(W34+X34+H34)*1.1+0.4*1.1 -> 8.000564 | AF34: =(P34*(1-I34)*1.1+R34)*(W34+X34+H34)*1.1+0.4*1.1 -> 10.722618
A35: https://www.1101.com/store/techo/en/2026/pc/detail_toolstoys/tt_cocc_okumi/ | C35: 01-2601-0105 | D35: 是 | H35: 0.05 | I35: 0 | J35: 1680 | K35: 110 | L35: 24 | M35: 35 | N35: 0.6 | O35: =max(L35*M35*N35/8000*1000,K35) -> 110 | P35: 33.6 | Q35: {=XLOOKUP(K35/1000, '运费（邮政）'!$A$2:$A$21, '运费（邮政）'!$B$2:$B$21, "超出范围", 1)} -> 1060 | R35: 12.99 | S35: =(V35+U35-Q35)/$B$1 -> 7.1770389 | T35: =P35+R35 -> 46.59 | U35: {=XLOOKUP(O35/1000, '运费（橙联）'!$A$2:$A$57, '运费（橙联）'!$B$2:$B$57, "超出范围", 1)} -> 1367 | V35: =(P35*'参数表'!$C$2*(1+'参数表'!$C$3))*$B$1+'参数表'!$C$4 -> 712.13952 | W35: 0.127 | X35: 0.0135 | Y35: =(P35*(1-I35)-AE35)*$B$1-J35-Q35 -> 868.93454 | Z35: =Y35/P35/$B$1 -> 0.18212075 | AA35: =Y35/J35 -> 0.51722294 | AB35: =(P35*(1-I35)+R35-AF35)*$B$1-J35-U35-V35 -> 1307.8433 | AC35: =AB35/T35/$B$1 -> 0.19768543 | AD35: =AB35/J35 -> 0.77847815 | AE35: =P35*(1-I35)*(1+'参数表'!$C$6)*(W35+X35+H35)*1.1+0.4*1.1 -> 8.184968 | AF35: =(P35*(1-I35)*1.1+R35)*(W35+X35+H35)*1.1+0.4*1.1 -> 10.907023
A36: https://www.1101.com/store/techo/en/2026/pc/detail_toolstoys/tt_liner_okumi/ | B36: https://www.amazon.co.jp/%E5%A5%A5%E8%A6%8B%E4%BC%8A%E4%BB%A3-%E3%81%BB%E3%81%BC%E6%97%A5%E3%81%AE%E4%B8%8B%E6%95%B7%E3%81%8D-HAPPY-taste-%E3%82%AB%E3%82%BA%E3%83%B3%E3%82%B5%E3%82%A4%E3%82%BA%E7%94%A8/dp/B0FG2JVCDV?th=1 | C36: 01-2601-0106 | D36: 是 | F36: set | G36: 4573630240512 | H36: 0.05 | I36: 0 | J36: 1710 | K36: 110 | L36: 34 | M36: 24 | N36: 2 | O36: =max(L36*M36*N36/8000*1000,K36) -> 204 | P36: 32.5 | Q36: {=XLOOKUP(K36/1000, '运费（邮政）'!$A$2:$A$21, '运费（邮政）'!$B$2:$B$21, "超出范围", 1)} -> 1060 | R36: 12.99 | S36: =(V36+U36-Q36)/$B$1 -> 8.5717711 | T36: =P36+R36 -> 45.49 | U36: {=XLOOKUP(O36/1000, '运费（橙联）'!$A$2:$A$57, '运费（橙联）'!$B$2:$B$57, "超出范围", 1)} -> 1581 | V36: =(P36*'参数表'!$C$2*(1+'参数表'!$C$3))*$B$1+'参数表'!$C$4 -> 696.1915 | W36: 0.127 | X36: 0.0135 | Y36: =(P36*(1-I36)-AE36)*$B$1-J36-Q36 -> 718.73942 | Z36: =Y36/P36/$B$1 -> 0.15573985 | AA36: =Y36/J36 -> 0.42031545 | AB36: =(P36*(1-I36)+R36-AF36)*$B$1-J36-U36-V36 -> 959.59619 | AC36: =AB36/T36/$B$1 -> 0.14855396 | AD36: =AB36/J36 -> 0.56116736 | AE36: =P36*(1-I36)*(1+'参数表'!$C$6)*(W36+X36+H36)*1.1+0.4*1.1 -> 7.9314125 | AF36: =(P36*(1-I36)*1.1+R36)*(W36+X36+H36)*1.1+0.4*1.1 -> 10.653467
A37: https://www.1101.com/store/techo/en/2026/pc/detail_toolstoys/tt_cc_okumi/ | C37: 01-2601-0107 | D37: 是 | H37: 0.05 | I37: 0 | J37: 1520 | K37: 80 | L37: 20 | M37: 20 | N37: 0.9 | O37: =max(L37*M37*N37/8000*1000,K37) -> 80 | P37: 32.8 | Q37: {=XLOOKUP(K37/1000, '运费（邮政）'!$A$2:$A$21, '运费（邮政）'!$B$2:$B$21, "超出范围", 1)} -> 880 | R37: 12.99 | S37: =(V37+U37-Q37)/$B$1 -> 7.377049 | T37: =P37+R37 -> 45.79 | U37: {=XLOOKUP(O37/1000, '运费（橙联）'!$A$2:$A$57, '运费（橙联）'!$B$2:$B$57, "超出范围", 1)} -> 1227 | V37: =(P37*'参数表'!$C$2*(1+'参数表'!$C$3))*$B$1+'参数表'!$C$4 -> 700.54096 | W37: 0.127 | X37: 0.0135 | Y37: =(P37*(1-I37)-AE37)*$B$1-J37-Q37 -> 1121.5199 | Z37: =Y37/P37/$B$1 -> 0.24079352 | AA37: =Y37/J37 -> 0.73784205 | AB37: =(P37*(1-I37)+R37-AF37)*$B$1-J37-U37-V37 -> 1532.0272 | AC37: =AB37/T37/$B$1 -> 0.23561747 | AD37: =AB37/J37 -> 1.0079126 | AE37: =P37*(1-I37)*(1+'参数表'!$C$6)*(W37+X37+H37)*1.1+0.4*1.1 -> 8.000564 | AF37: =(P37*(1-I37)*1.1+R37)*(W37+X37+H37)*1.1+0.4*1.1 -> 10.722618
A38: https://www.amazon.co.jp/dp/B0DCD2CSS1?tag=webspire_new-22&linkCode=osi&th=1&psc=1 | C38: 01-2601-0108 | D38: 是 | G38: 4988031675755 | H38: 0.05 | I38: 0 | J38: 2750 | K38: 210 | L38: 14.1 | M38: 12.4 | N38: 0.9 | O38: =max(L38*M38*N38/8000*1000,K38) -> 210 | P38: 44.8 | Q38: {=XLOOKUP(K38/1000, '运费（邮政）'!$A$2:$A$21, '运费（邮政）'!$B$2:$B$21, "超出范围", 1)} -> 1240 | R38: 15.99 | S38: =(V38+U38-Q38)/$B$1 -> 8.5599955 | T38: =P38+R38 -> 60.79 | U38: {=XLOOKUP(O38/1000, '运费（橙联）'!$A$2:$A$57, '运费（橙联）'!$B$2:$B$57, "超出范围", 1)} -> 1581 | V38: =(P38*'参数表'!$C$2*(1+'参数表'!$C$3))*$B$1+'参数表'!$C$4 -> 874.51936 | W38: 0.127 | X38: 0.0135 | Y38: =(P38*(1-I38)-AE38)*$B$1-J38-Q38 -> 842.73939 | Z38: =Y38/P38/$B$1 -> 0.13247287 | AA38: =Y38/J38 -> 0.30645069 | AB38: =(P38*(1-I38)+R38-AF38)*$B$1-J38-U38-V38 -> 1422 | AC38: =AB38/T38/$B$1 -> 0.16473243 | AD38: =AB38/J38 -> 0.51709091 | AE38: =P38*(1-I38)*(1+'参数表'!$C$6)*(W38+X38+H38)*1.1+0.4*1.1 -> 10.766624 | AF38: =(P38*(1-I38)*1.1+R38)*(W38+X38+H38)*1.1+0.4*1.1 -> 14.117328
A39: https://www.amazon.co.jp/%E3%80%90Amazon-co-jp-%E9%99%90%E5%AE%9A%E3%80%91%E3%82%B7%E3%83%AB%E3%83%90%E3%83%8B%E3%82%A2%E3%83%95%E3%82%A1%E3%83%9F%E3%83%AA%E3%83%BC-%E8%B5%A4%E3%81%84%E5%B1%8B%E6%A0%B9%E3%81%AE%E5%A4%A7%E3%81%8D%E3%81%AA%E3%81%8A%E5%AE%B6-%E5%B1%8B%E6%A0%B9%E8%A3%8F%E3%81%AF%E3%81%B2%E3%81%BF%E3%81%A4%E3%81%AE%E3%81%8A%E9%83%A8%E5%B1%8B-22-RZ/dp/B0BBT9GZ5J/ref=sr_1_1_sspa?crid=2L1N1L8X8E7GY&dib=eyJ2IjoiMSJ9.SpscTIEXrgIcKzrEJ6cefh34U0X21LOcjx472J8jcOsnVKIWjGXyYsWKflM6BUPS2TEoMLTm319CRoIev6kET7JQriElusxqss7RosSabpZA0nLX1ouwCl8hW6cVmS23nBBgg_udd12w7IU0Q0ZAohvCF4S2dngmVnGu1Zo-54VIDI023hGPpQcZIzO0qZePvd6JEe8GaUmFkcWrQqLA1Yo2q9cMy27xP6aaVfODo6eM2SW9DNcA9VR3DgdQ_mPhE6e-ZB35jrZu9CPG1FFPt4M7ND3ZP4U5FH5m0v1y9W4.6OL6uvuO6FxJmSNEddPuJou_Gpxg2CNEXLBsd4xf97c&dib_tag=se&keywords=sylvanian%2Bfamilies&qid=1768886676&sprefix=sylvanian%2Caps%2C243&sr=8-1-spons&sp_csd=d2lkZ2V0TmFtZT1zcF9hdGY&th=1 | C39: 01-2601-0109 | D39: 是 | F39: 大件 | G39: 4905040152015 | H39: 0.05 | I39: 0 | J39: 11000 | K39: 6000 | L39: 65 | M39: 25 | N39: 40 | O39: =max(L39*M39*N39/8000*1000,K39) -> 8125 | P39: 142 | Q39: {=XLOOKUP(K39/1000, '运费（邮政）'!$A$2:$A$21, '运费（邮政）'!$B$2:$B$21, "超出范围", 1)} -> 超出范围 | R39: 280 | S39: =(V39+U39-Q39)/$B$1 -> #VALUE! | T39: =P39+R39 -> 422 | U39: {=XLOOKUP(O39/1000, '运费（橙联）'!$A$2:$A$57, '运费（橙联）'!$B$2:$B$57, "超出范围", 1)} -> 9884 | V39: =(P39*'参数表'!$C$2*(1+'参数表'!$C$3))*$B$1+'参数表'!$C$4 -> 2283.7444 | W39: 0.127 | X39: 0.0135 | Y39: =(P39*(1-I39)-AE39)*$B$1-J39-Q39 -> #VALUE! | Z39: =Y39/P39/$B$1 -> #VALUE! | AA39: =Y39/J39 -> #VALUE! | AB39: =(P39*(1-I39)+R39-AF39)*$B$1-J39-U39-V39 -> 23714.165 | AC39: =AB39/T39/$B$1 -> 0.39573735 | AD39: =AB39/J39 -> 2.1558332 | AE39: =P39*(1-I39)*(1+'参数表'!$C$6)*(W39+X39+H39)*1.1+0.4*1.1 -> 33.17171 | AF39: =(P39*(1-I39)*1.1+R39)*(W39+X39+H39)*1.1+0.4*1.1 -> 91.84571
A40: https://www.1101.com/store/techo/en/2026/pc/detail_cover/cc26_okumi/ | C40: 01-2601-0110 | D40: 是 | H40: 0.05 | I40: 0 | J40: 6580 | K40: 170 | L40: 33.7 | M40: 28 | N40: 3 | O40: =max(L40*M40*N40/8000*1000,K40) -> 353.85 | P40: 89.54 | Q40: {=XLOOKUP(K40/1000, '运费（邮政）'!$A$2:$A$21, '运费（邮政）'!$B$2:$B$21, "超出范围", 1)} -> 1060 | R40: 28.99 | S40: =(V40+U40-Q40)/$B$1 -> 15.782879 | T40: =P40+R40 -> 118.53 | U40: {=XLOOKUP(O40/1000, '运费（橙联）'!$A$2:$A$57, '运费（橙联）'!$B$2:$B$57, "超出范围", 1)} -> 1778 | V40: =(P40*'参数表'!$C$2*(1+'参数表'!$C$3))*$B$1+'参数表'!$C$4 -> 1523.1688 | W40: 0.127 | X40: 0.0135 | Y40: =(P40*(1-I40)-AE40)*$B$1-J40-Q40 -> 2081.4027 | Z40: =Y40/P40/$B$1 -> 0.16370075 | AA40: =Y40/J40 -> 0.3163226 | AB40: =(P40*(1-I40)+R40-AF40)*$B$1-J40-U40-V40 -> 3094.1845 | AC40: =AB40/T40/$B$1 -> 0.18383558 | AD40: =AB40/J40 -> 0.47024081 | AE40: =P40*(1-I40)*(1+'参数表'!$C$6)*(W40+X40+H40)*1.1+0.4*1.1 -> 21.079418 | AF40: =(P40*(1-I40)*1.1+R40)*(W40+X40+H40)*1.1+0.4*1.1 -> 27.154272
...

Sheet 工作表13

Sheet UPC查重表
A1: 4571614702230
A2: 4988005486547
A3: 4547366408959
A4: 4988031675755
A5: 4580357661605
A6: 4972525052801
A7: 4901601288728
A8: 4972525053136
A9: 4901601937343
A10: 4901601236385
A11: 4901601937367
A12: 4901601240337
A13: 4910299340854
A14: 4521329368009
A15: 9784041156834
A16: 4521329266527
A17: 4549660863748
A18: 9784092274266
A19: 4582769865206
A20: 75678599316
A21: 4972525053297
A22: 795864762897
A23: 4972525053310
A24: 4972525053181
A25: 4972525053402
A26: 4972525053419
A27: 4972525021005
A28: 4972525021012
A29: 4972525050586
A30: 4943674415809
A31: 4988002437269
A32: 4547366754759
A33: 4988001131991
A34: 4943674402915
A35: 4547366710892
A36: 4947864600518
A37: 4988031754412
A38: 4524334001473
A39: 4582798814466
A40: 4943674108947
...

Sheet 运费（邮政）
B1: 日元
A2: 0.1 | B2: 880
A3: 0.2 | B3: 1060
A4: 0.3 | B4: 1240
A5: 0.4 | B5: 1420
A6: 0.5 | B6: 1600
A7: 0.6 | B7: 1780
A8: 0.7 | B8: 1960
A9: 0.8 | B9: 2140
A10: 0.9 | B10: 2320
A11: 1 | B11: 2500
A12: 1.1 | B12: 2680
A13: 1.2 | B13: 2860
... A21: 2 | B21: 4300

Sheet 运费（橙联）
A1: 重量上限 (kg) | B1: 运费 (JPY)
A2: 0.1 | B2: 1227
A3: 0.2 | B3: 1367
A4: 0.3 | B4: 1581
A5: 0.4 | B5: 1778
A6: 0.5 | B6: 2060
A7: 0.6 | B7: 2222
A8: 0.7 | B8: 2321
A9: 0.8 | B9: 2703
A10: 0.9 | B10: 2820
A11: 1 | B11: 3020
A12: 1.1 | B12: 3136
A13: 1.2 | B13: 3250
... A57: 20 | B57: 23946

Sheet 参数表
D1: 备注
B2: 关税 | C2: 0.1
B3: 关税手续费 | C3: 0.021 | D3: 关税基础上
B4: 通关手续费 | C4: 225 | D4: 日元
B5: eBay交易手续费 | C5: 0.4 | D5: 美元/笔
B6: 消费税、VAT、GST | C6: 0.1 | D6: 预设
